[2025-04-21T02:43:36.459+0000] {local_task_job_runner.py:123} INFO - ::group::Pre task execution logs
[2025-04-21T02:43:36.465+0000] {taskinstance.py:2612} INFO - Dependencies all met for dep_context=non-requeueable deps ti=<TaskInstance: dbt_run_dag.run_dbt_models manual__2025-04-21T02:43:36.076243+00:00 [queued]>
[2025-04-21T02:43:36.468+0000] {taskinstance.py:2612} INFO - Dependencies all met for dep_context=requeueable deps ti=<TaskInstance: dbt_run_dag.run_dbt_models manual__2025-04-21T02:43:36.076243+00:00 [queued]>
[2025-04-21T02:43:36.468+0000] {taskinstance.py:2865} INFO - Starting attempt 1 of 2
[2025-04-21T02:43:36.474+0000] {taskinstance.py:2888} INFO - Executing <Task(BashOperator): run_dbt_models> on 2025-04-21 02:43:36.076243+00:00
[2025-04-21T02:43:36.476+0000] {standard_task_runner.py:72} INFO - Started process 790 to run task
[2025-04-21T02:43:36.479+0000] {standard_task_runner.py:104} INFO - Running: ['***', 'tasks', 'run', 'dbt_run_dag', 'run_dbt_models', 'manual__2025-04-21T02:43:36.076243+00:00', '--job-id', '9', '--raw', '--subdir', 'DAGS_FOLDER/dbt_run_dag.py', '--cfg-path', '/tmp/tmpuotaqppf']
[2025-04-21T02:43:36.480+0000] {standard_task_runner.py:105} INFO - Job 9: Subtask run_dbt_models
[2025-04-21T02:43:36.504+0000] {task_command.py:467} INFO - Running <TaskInstance: dbt_run_dag.run_dbt_models manual__2025-04-21T02:43:36.076243+00:00 [running]> on host 864bcad9e084
[2025-04-21T02:43:36.540+0000] {taskinstance.py:3131} INFO - Exporting env vars: AIRFLOW_CTX_DAG_OWNER='***' AIRFLOW_CTX_DAG_ID='dbt_run_dag' AIRFLOW_CTX_TASK_ID='run_dbt_models' AIRFLOW_CTX_EXECUTION_DATE='2025-04-21T02:43:36.076243+00:00' AIRFLOW_CTX_TRY_NUMBER='1' AIRFLOW_CTX_DAG_RUN_ID='manual__2025-04-21T02:43:36.076243+00:00'
[2025-04-21T02:43:36.541+0000] {taskinstance.py:731} INFO - ::endgroup::
[2025-04-21T02:43:36.550+0000] {subprocess.py:63} INFO - Tmp dir root location: /tmp
[2025-04-21T02:43:36.552+0000] {subprocess.py:75} INFO - Running command: ['/usr/bin/bash', '-c', 'cd /opt/***/dbt_lab2_music && dbt run --profiles-dir /home/***/.dbt']
[2025-04-21T02:43:36.560+0000] {subprocess.py:86} INFO - Output:
[2025-04-21T02:43:37.409+0000] {subprocess.py:93} INFO - Usage: dbt run [OPTIONS]
[2025-04-21T02:43:37.409+0000] {subprocess.py:93} INFO - Try 'dbt run -h' for help.
[2025-04-21T02:43:37.410+0000] {subprocess.py:93} INFO - 
[2025-04-21T02:43:37.410+0000] {subprocess.py:93} INFO - Error: Invalid value for '--profiles-dir': Path '/home/***/.dbt' does not exist.
[2025-04-21T02:43:37.479+0000] {subprocess.py:97} INFO - Command exited with return code 2
[2025-04-21T02:43:37.486+0000] {taskinstance.py:3310} ERROR - Task failed with exception
Traceback (most recent call last):
  File "/home/airflow/.local/lib/python3.10/site-packages/airflow/models/taskinstance.py", line 767, in _execute_task
    result = _execute_callable(context=context, **execute_callable_kwargs)
  File "/home/airflow/.local/lib/python3.10/site-packages/airflow/models/taskinstance.py", line 733, in _execute_callable
    return ExecutionCallableRunner(
  File "/home/airflow/.local/lib/python3.10/site-packages/airflow/utils/operator_helpers.py", line 252, in run
    return self.func(*args, **kwargs)
  File "/home/airflow/.local/lib/python3.10/site-packages/airflow/models/baseoperator.py", line 406, in wrapper
    return func(self, *args, **kwargs)
  File "/home/airflow/.local/lib/python3.10/site-packages/airflow/operators/bash.py", line 249, in execute
    raise AirflowException(
airflow.exceptions.AirflowException: Bash command failed. The command returned a non-zero exit code 2.
[2025-04-21T02:43:37.489+0000] {taskinstance.py:1225} INFO - Marking task as UP_FOR_RETRY. dag_id=dbt_run_dag, task_id=run_dbt_models, run_id=manual__2025-04-21T02:43:36.076243+00:00, execution_date=20250421T024336, start_date=20250421T024336, end_date=20250421T024337
[2025-04-21T02:43:37.496+0000] {taskinstance.py:340} INFO - ::group::Post task execution logs
[2025-04-21T02:43:37.497+0000] {standard_task_runner.py:124} ERROR - Failed to execute job 9 for task run_dbt_models (Bash command failed. The command returned a non-zero exit code 2.; 790)
Traceback (most recent call last):
  File "/home/airflow/.local/lib/python3.10/site-packages/airflow/task/task_runner/standard_task_runner.py", line 117, in _start_by_fork
    ret = args.func(args, dag=self.dag)
  File "/home/airflow/.local/lib/python3.10/site-packages/airflow/cli/cli_config.py", line 49, in command
    return func(*args, **kwargs)
  File "/home/airflow/.local/lib/python3.10/site-packages/airflow/utils/cli.py", line 115, in wrapper
    return f(*args, **kwargs)
  File "/home/airflow/.local/lib/python3.10/site-packages/airflow/cli/commands/task_command.py", line 483, in task_run
    task_return_code = _run_task_by_selected_method(args, _dag, ti)
  File "/home/airflow/.local/lib/python3.10/site-packages/airflow/cli/commands/task_command.py", line 256, in _run_task_by_selected_method
    return _run_raw_task(args, ti)
  File "/home/airflow/.local/lib/python3.10/site-packages/airflow/cli/commands/task_command.py", line 341, in _run_raw_task
    return ti._run_raw_task(
  File "/home/airflow/.local/lib/python3.10/site-packages/airflow/utils/session.py", line 97, in wrapper
    return func(*args, session=session, **kwargs)
  File "/home/airflow/.local/lib/python3.10/site-packages/airflow/models/taskinstance.py", line 3004, in _run_raw_task
    return _run_raw_task(
  File "/home/airflow/.local/lib/python3.10/site-packages/airflow/models/taskinstance.py", line 273, in _run_raw_task
    TaskInstance._execute_task_with_callbacks(
  File "/home/airflow/.local/lib/python3.10/site-packages/airflow/models/taskinstance.py", line 3158, in _execute_task_with_callbacks
    result = self._execute_task(context, task_orig)
  File "/home/airflow/.local/lib/python3.10/site-packages/airflow/models/taskinstance.py", line 3182, in _execute_task
    return _execute_task(self, context, task_orig)
  File "/home/airflow/.local/lib/python3.10/site-packages/airflow/models/taskinstance.py", line 767, in _execute_task
    result = _execute_callable(context=context, **execute_callable_kwargs)
  File "/home/airflow/.local/lib/python3.10/site-packages/airflow/models/taskinstance.py", line 733, in _execute_callable
    return ExecutionCallableRunner(
  File "/home/airflow/.local/lib/python3.10/site-packages/airflow/utils/operator_helpers.py", line 252, in run
    return self.func(*args, **kwargs)
  File "/home/airflow/.local/lib/python3.10/site-packages/airflow/models/baseoperator.py", line 406, in wrapper
    return func(self, *args, **kwargs)
  File "/home/airflow/.local/lib/python3.10/site-packages/airflow/operators/bash.py", line 249, in execute
    raise AirflowException(
airflow.exceptions.AirflowException: Bash command failed. The command returned a non-zero exit code 2.
[2025-04-21T02:43:37.509+0000] {local_task_job_runner.py:266} INFO - Task exited with return code 1
[2025-04-21T02:43:37.516+0000] {taskinstance.py:3900} INFO - 0 downstream tasks scheduled from follow-on schedule check
[2025-04-21T02:43:37.517+0000] {local_task_job_runner.py:245} INFO - ::endgroup::
