[2025-04-19T04:24:57.382+0000] {local_task_job_runner.py:123} INFO - ::group::Pre task execution logs
[2025-04-19T04:24:57.389+0000] {taskinstance.py:2612} INFO - Dependencies all met for dep_context=non-requeueable deps ti=<TaskInstance: dbt_run_dag.run_dbt_models manual__2025-04-19T04:19:56.250960+00:00 [queued]>
[2025-04-19T04:24:57.393+0000] {taskinstance.py:2612} INFO - Dependencies all met for dep_context=requeueable deps ti=<TaskInstance: dbt_run_dag.run_dbt_models manual__2025-04-19T04:19:56.250960+00:00 [queued]>
[2025-04-19T04:24:57.394+0000] {taskinstance.py:2865} INFO - Starting attempt 2 of 2
[2025-04-19T04:24:57.400+0000] {taskinstance.py:2888} INFO - Executing <Task(BashOperator): run_dbt_models> on 2025-04-19 04:19:56.250960+00:00
[2025-04-19T04:24:57.404+0000] {standard_task_runner.py:72} INFO - Started process 510 to run task
[2025-04-19T04:24:57.406+0000] {standard_task_runner.py:104} INFO - Running: ['***', 'tasks', 'run', 'dbt_run_dag', 'run_dbt_models', 'manual__2025-04-19T04:19:56.250960+00:00', '--job-id', '7', '--raw', '--subdir', 'DAGS_FOLDER/dbt_run_dag.py', '--cfg-path', '/tmp/tmpzf6zco77']
[2025-04-19T04:24:57.409+0000] {standard_task_runner.py:105} INFO - Job 7: Subtask run_dbt_models
[2025-04-19T04:24:57.428+0000] {task_command.py:467} INFO - Running <TaskInstance: dbt_run_dag.run_dbt_models manual__2025-04-19T04:19:56.250960+00:00 [running]> on host 0f91371101b0
[2025-04-19T04:24:57.455+0000] {taskinstance.py:3131} INFO - Exporting env vars: AIRFLOW_CTX_DAG_OWNER='***' AIRFLOW_CTX_DAG_ID='dbt_run_dag' AIRFLOW_CTX_TASK_ID='run_dbt_models' AIRFLOW_CTX_EXECUTION_DATE='2025-04-19T04:19:56.250960+00:00' AIRFLOW_CTX_TRY_NUMBER='2' AIRFLOW_CTX_DAG_RUN_ID='manual__2025-04-19T04:19:56.250960+00:00'
[2025-04-19T04:24:57.455+0000] {taskinstance.py:731} INFO - ::endgroup::
[2025-04-19T04:24:57.462+0000] {subprocess.py:63} INFO - Tmp dir root location: /tmp
[2025-04-19T04:24:57.462+0000] {subprocess.py:75} INFO - Running command: ['/usr/bin/bash', '-c', 'source /Users/chandanasreya/Downloads/lab2/venv/bin/activate && dbt run --project-dir /Users/chandanasreya/Downloads/lab2/dbt_lab2_music']
[2025-04-19T04:24:57.465+0000] {subprocess.py:86} INFO - Output:
[2025-04-19T04:24:57.467+0000] {subprocess.py:93} INFO - /usr/bin/bash: line 1: /Users/chandanasreya/Downloads/lab2/venv/bin/activate: No such file or directory
[2025-04-19T04:24:57.468+0000] {subprocess.py:97} INFO - Command exited with return code 1
[2025-04-19T04:24:57.473+0000] {taskinstance.py:3310} ERROR - Task failed with exception
Traceback (most recent call last):
  File "/home/airflow/.local/lib/python3.10/site-packages/airflow/models/taskinstance.py", line 767, in _execute_task
    result = _execute_callable(context=context, **execute_callable_kwargs)
  File "/home/airflow/.local/lib/python3.10/site-packages/airflow/models/taskinstance.py", line 733, in _execute_callable
    return ExecutionCallableRunner(
  File "/home/airflow/.local/lib/python3.10/site-packages/airflow/utils/operator_helpers.py", line 252, in run
    return self.func(*args, **kwargs)
  File "/home/airflow/.local/lib/python3.10/site-packages/airflow/models/baseoperator.py", line 406, in wrapper
    return func(self, *args, **kwargs)
  File "/home/airflow/.local/lib/python3.10/site-packages/airflow/operators/bash.py", line 249, in execute
    raise AirflowException(
airflow.exceptions.AirflowException: Bash command failed. The command returned a non-zero exit code 1.
[2025-04-19T04:24:57.475+0000] {taskinstance.py:1225} INFO - Marking task as FAILED. dag_id=dbt_run_dag, task_id=run_dbt_models, run_id=manual__2025-04-19T04:19:56.250960+00:00, execution_date=20250419T041956, start_date=20250419T042457, end_date=20250419T042457
[2025-04-19T04:24:57.480+0000] {taskinstance.py:340} INFO - ::group::Post task execution logs
[2025-04-19T04:24:57.480+0000] {standard_task_runner.py:124} ERROR - Failed to execute job 7 for task run_dbt_models (Bash command failed. The command returned a non-zero exit code 1.; 510)
Traceback (most recent call last):
  File "/home/airflow/.local/lib/python3.10/site-packages/airflow/task/task_runner/standard_task_runner.py", line 117, in _start_by_fork
    ret = args.func(args, dag=self.dag)
  File "/home/airflow/.local/lib/python3.10/site-packages/airflow/cli/cli_config.py", line 49, in command
    return func(*args, **kwargs)
  File "/home/airflow/.local/lib/python3.10/site-packages/airflow/utils/cli.py", line 115, in wrapper
    return f(*args, **kwargs)
  File "/home/airflow/.local/lib/python3.10/site-packages/airflow/cli/commands/task_command.py", line 483, in task_run
    task_return_code = _run_task_by_selected_method(args, _dag, ti)
  File "/home/airflow/.local/lib/python3.10/site-packages/airflow/cli/commands/task_command.py", line 256, in _run_task_by_selected_method
    return _run_raw_task(args, ti)
  File "/home/airflow/.local/lib/python3.10/site-packages/airflow/cli/commands/task_command.py", line 341, in _run_raw_task
    return ti._run_raw_task(
  File "/home/airflow/.local/lib/python3.10/site-packages/airflow/utils/session.py", line 97, in wrapper
    return func(*args, session=session, **kwargs)
  File "/home/airflow/.local/lib/python3.10/site-packages/airflow/models/taskinstance.py", line 3004, in _run_raw_task
    return _run_raw_task(
  File "/home/airflow/.local/lib/python3.10/site-packages/airflow/models/taskinstance.py", line 273, in _run_raw_task
    TaskInstance._execute_task_with_callbacks(
  File "/home/airflow/.local/lib/python3.10/site-packages/airflow/models/taskinstance.py", line 3158, in _execute_task_with_callbacks
    result = self._execute_task(context, task_orig)
  File "/home/airflow/.local/lib/python3.10/site-packages/airflow/models/taskinstance.py", line 3182, in _execute_task
    return _execute_task(self, context, task_orig)
  File "/home/airflow/.local/lib/python3.10/site-packages/airflow/models/taskinstance.py", line 767, in _execute_task
    result = _execute_callable(context=context, **execute_callable_kwargs)
  File "/home/airflow/.local/lib/python3.10/site-packages/airflow/models/taskinstance.py", line 733, in _execute_callable
    return ExecutionCallableRunner(
  File "/home/airflow/.local/lib/python3.10/site-packages/airflow/utils/operator_helpers.py", line 252, in run
    return self.func(*args, **kwargs)
  File "/home/airflow/.local/lib/python3.10/site-packages/airflow/models/baseoperator.py", line 406, in wrapper
    return func(self, *args, **kwargs)
  File "/home/airflow/.local/lib/python3.10/site-packages/airflow/operators/bash.py", line 249, in execute
    raise AirflowException(
airflow.exceptions.AirflowException: Bash command failed. The command returned a non-zero exit code 1.
[2025-04-19T04:24:57.505+0000] {local_task_job_runner.py:266} INFO - Task exited with return code 1
[2025-04-19T04:24:57.513+0000] {taskinstance.py:3900} INFO - 0 downstream tasks scheduled from follow-on schedule check
[2025-04-19T04:24:57.514+0000] {local_task_job_runner.py:245} INFO - ::endgroup::
