[2025-04-21T02:20:30.378+0000] {local_task_job_runner.py:123} INFO - ::group::Pre task execution logs
[2025-04-21T02:20:30.384+0000] {taskinstance.py:2612} INFO - Dependencies all met for dep_context=non-requeueable deps ti=<TaskInstance: dbt_run_dag.run_dbt_models scheduled__2025-04-20T00:00:00+00:00 [queued]>
[2025-04-21T02:20:30.387+0000] {taskinstance.py:2612} INFO - Dependencies all met for dep_context=requeueable deps ti=<TaskInstance: dbt_run_dag.run_dbt_models scheduled__2025-04-20T00:00:00+00:00 [queued]>
[2025-04-21T02:20:30.388+0000] {taskinstance.py:2865} INFO - Starting attempt 2 of 2
[2025-04-21T02:20:30.393+0000] {taskinstance.py:2888} INFO - Executing <Task(BashOperator): run_dbt_models> on 2025-04-20 00:00:00+00:00
[2025-04-21T02:20:30.398+0000] {standard_task_runner.py:104} INFO - Running: ['***', 'tasks', 'run', 'dbt_run_dag', 'run_dbt_models', 'scheduled__2025-04-20T00:00:00+00:00', '--job-id', '10', '--raw', '--subdir', 'DAGS_FOLDER/dbt_run_dag.py', '--cfg-path', '/tmp/tmp9q_tc5wl']
[2025-04-21T02:20:30.395+0000] {standard_task_runner.py:72} INFO - Started process 476 to run task
[2025-04-21T02:20:30.400+0000] {standard_task_runner.py:105} INFO - Job 10: Subtask run_dbt_models
[2025-04-21T02:20:30.426+0000] {task_command.py:467} INFO - Running <TaskInstance: dbt_run_dag.run_dbt_models scheduled__2025-04-20T00:00:00+00:00 [running]> on host 0572d59512e5
[2025-04-21T02:20:30.461+0000] {taskinstance.py:3131} INFO - Exporting env vars: AIRFLOW_CTX_DAG_OWNER='***' AIRFLOW_CTX_DAG_ID='dbt_run_dag' AIRFLOW_CTX_TASK_ID='run_dbt_models' AIRFLOW_CTX_EXECUTION_DATE='2025-04-20T00:00:00+00:00' AIRFLOW_CTX_TRY_NUMBER='2' AIRFLOW_CTX_DAG_RUN_ID='scheduled__2025-04-20T00:00:00+00:00'
[2025-04-21T02:20:30.461+0000] {taskinstance.py:731} INFO - ::endgroup::
[2025-04-21T02:20:30.468+0000] {subprocess.py:63} INFO - Tmp dir root location: /tmp
[2025-04-21T02:20:30.468+0000] {subprocess.py:75} INFO - Running command: ['/usr/bin/bash', '-c', 'cd /opt/***/dbt_lab2_music && dbt run']
[2025-04-21T02:20:30.472+0000] {subprocess.py:86} INFO - Output:
[2025-04-21T02:20:31.327+0000] {subprocess.py:93} INFO - Usage: dbt run [OPTIONS]
[2025-04-21T02:20:31.327+0000] {subprocess.py:93} INFO - Try 'dbt run -h' for help.
[2025-04-21T02:20:31.327+0000] {subprocess.py:93} INFO - 
[2025-04-21T02:20:31.328+0000] {subprocess.py:93} INFO - Error: Invalid value for '--profiles-dir': Path '/home/***/.dbt' does not exist.
[2025-04-21T02:20:31.442+0000] {subprocess.py:97} INFO - Command exited with return code 2
[2025-04-21T02:20:31.448+0000] {taskinstance.py:3310} ERROR - Task failed with exception
Traceback (most recent call last):
  File "/home/airflow/.local/lib/python3.10/site-packages/airflow/models/taskinstance.py", line 767, in _execute_task
    result = _execute_callable(context=context, **execute_callable_kwargs)
  File "/home/airflow/.local/lib/python3.10/site-packages/airflow/models/taskinstance.py", line 733, in _execute_callable
    return ExecutionCallableRunner(
  File "/home/airflow/.local/lib/python3.10/site-packages/airflow/utils/operator_helpers.py", line 252, in run
    return self.func(*args, **kwargs)
  File "/home/airflow/.local/lib/python3.10/site-packages/airflow/models/baseoperator.py", line 406, in wrapper
    return func(self, *args, **kwargs)
  File "/home/airflow/.local/lib/python3.10/site-packages/airflow/operators/bash.py", line 249, in execute
    raise AirflowException(
airflow.exceptions.AirflowException: Bash command failed. The command returned a non-zero exit code 2.
[2025-04-21T02:20:31.450+0000] {taskinstance.py:1225} INFO - Marking task as FAILED. dag_id=dbt_run_dag, task_id=run_dbt_models, run_id=scheduled__2025-04-20T00:00:00+00:00, execution_date=20250420T000000, start_date=20250421T022030, end_date=20250421T022031
[2025-04-21T02:20:31.456+0000] {taskinstance.py:340} INFO - ::group::Post task execution logs
[2025-04-21T02:20:31.456+0000] {standard_task_runner.py:124} ERROR - Failed to execute job 10 for task run_dbt_models (Bash command failed. The command returned a non-zero exit code 2.; 476)
Traceback (most recent call last):
  File "/home/airflow/.local/lib/python3.10/site-packages/airflow/task/task_runner/standard_task_runner.py", line 117, in _start_by_fork
    ret = args.func(args, dag=self.dag)
  File "/home/airflow/.local/lib/python3.10/site-packages/airflow/cli/cli_config.py", line 49, in command
    return func(*args, **kwargs)
  File "/home/airflow/.local/lib/python3.10/site-packages/airflow/utils/cli.py", line 115, in wrapper
    return f(*args, **kwargs)
  File "/home/airflow/.local/lib/python3.10/site-packages/airflow/cli/commands/task_command.py", line 483, in task_run
    task_return_code = _run_task_by_selected_method(args, _dag, ti)
  File "/home/airflow/.local/lib/python3.10/site-packages/airflow/cli/commands/task_command.py", line 256, in _run_task_by_selected_method
    return _run_raw_task(args, ti)
  File "/home/airflow/.local/lib/python3.10/site-packages/airflow/cli/commands/task_command.py", line 341, in _run_raw_task
    return ti._run_raw_task(
  File "/home/airflow/.local/lib/python3.10/site-packages/airflow/utils/session.py", line 97, in wrapper
    return func(*args, session=session, **kwargs)
  File "/home/airflow/.local/lib/python3.10/site-packages/airflow/models/taskinstance.py", line 3004, in _run_raw_task
    return _run_raw_task(
  File "/home/airflow/.local/lib/python3.10/site-packages/airflow/models/taskinstance.py", line 273, in _run_raw_task
    TaskInstance._execute_task_with_callbacks(
  File "/home/airflow/.local/lib/python3.10/site-packages/airflow/models/taskinstance.py", line 3158, in _execute_task_with_callbacks
    result = self._execute_task(context, task_orig)
  File "/home/airflow/.local/lib/python3.10/site-packages/airflow/models/taskinstance.py", line 3182, in _execute_task
    return _execute_task(self, context, task_orig)
  File "/home/airflow/.local/lib/python3.10/site-packages/airflow/models/taskinstance.py", line 767, in _execute_task
    result = _execute_callable(context=context, **execute_callable_kwargs)
  File "/home/airflow/.local/lib/python3.10/site-packages/airflow/models/taskinstance.py", line 733, in _execute_callable
    return ExecutionCallableRunner(
  File "/home/airflow/.local/lib/python3.10/site-packages/airflow/utils/operator_helpers.py", line 252, in run
    return self.func(*args, **kwargs)
  File "/home/airflow/.local/lib/python3.10/site-packages/airflow/models/baseoperator.py", line 406, in wrapper
    return func(self, *args, **kwargs)
  File "/home/airflow/.local/lib/python3.10/site-packages/airflow/operators/bash.py", line 249, in execute
    raise AirflowException(
airflow.exceptions.AirflowException: Bash command failed. The command returned a non-zero exit code 2.
[2025-04-21T02:20:31.496+0000] {local_task_job_runner.py:266} INFO - Task exited with return code 1
[2025-04-21T02:20:31.503+0000] {taskinstance.py:3900} INFO - 0 downstream tasks scheduled from follow-on schedule check
[2025-04-21T02:20:31.504+0000] {local_task_job_runner.py:245} INFO - ::endgroup::
[2025-04-21T02:32:54.898+0000] {local_task_job_runner.py:123} INFO - ::group::Pre task execution logs
[2025-04-21T02:32:54.909+0000] {taskinstance.py:2612} INFO - Dependencies all met for dep_context=non-requeueable deps ti=<TaskInstance: dbt_run_dag.run_dbt_models scheduled__2025-04-20T00:00:00+00:00 [queued]>
[2025-04-21T02:32:54.914+0000] {taskinstance.py:2612} INFO - Dependencies all met for dep_context=requeueable deps ti=<TaskInstance: dbt_run_dag.run_dbt_models scheduled__2025-04-20T00:00:00+00:00 [queued]>
[2025-04-21T02:32:54.915+0000] {taskinstance.py:2865} INFO - Starting attempt 2 of 2
[2025-04-21T02:32:54.921+0000] {taskinstance.py:2888} INFO - Executing <Task(BashOperator): run_dbt_models> on 2025-04-20 00:00:00+00:00
[2025-04-21T02:32:54.923+0000] {standard_task_runner.py:72} INFO - Started process 457 to run task
[2025-04-21T02:32:54.925+0000] {standard_task_runner.py:104} INFO - Running: ['***', 'tasks', 'run', 'dbt_run_dag', 'run_dbt_models', 'scheduled__2025-04-20T00:00:00+00:00', '--job-id', '5', '--raw', '--subdir', 'DAGS_FOLDER/dbt_run_dag.py', '--cfg-path', '/tmp/tmpu37848i2']
[2025-04-21T02:32:54.927+0000] {standard_task_runner.py:105} INFO - Job 5: Subtask run_dbt_models
[2025-04-21T02:32:54.946+0000] {task_command.py:467} INFO - Running <TaskInstance: dbt_run_dag.run_dbt_models scheduled__2025-04-20T00:00:00+00:00 [running]> on host 864bcad9e084
[2025-04-21T02:32:54.973+0000] {taskinstance.py:3131} INFO - Exporting env vars: AIRFLOW_CTX_DAG_OWNER='***' AIRFLOW_CTX_DAG_ID='dbt_run_dag' AIRFLOW_CTX_TASK_ID='run_dbt_models' AIRFLOW_CTX_EXECUTION_DATE='2025-04-20T00:00:00+00:00' AIRFLOW_CTX_TRY_NUMBER='2' AIRFLOW_CTX_DAG_RUN_ID='scheduled__2025-04-20T00:00:00+00:00'
[2025-04-21T02:32:54.973+0000] {taskinstance.py:731} INFO - ::endgroup::
[2025-04-21T02:32:54.979+0000] {subprocess.py:63} INFO - Tmp dir root location: /tmp
[2025-04-21T02:32:54.979+0000] {subprocess.py:75} INFO - Running command: ['/usr/bin/bash', '-c', 'cd /opt/***/dbt_lab2_music && dbt run --profiles-dir /home/***/.dbt']
[2025-04-21T02:32:54.983+0000] {subprocess.py:86} INFO - Output:
[2025-04-21T02:32:55.897+0000] {subprocess.py:93} INFO - Usage: dbt run [OPTIONS]
[2025-04-21T02:32:55.898+0000] {subprocess.py:93} INFO - Try 'dbt run -h' for help.
[2025-04-21T02:32:55.898+0000] {subprocess.py:93} INFO - 
[2025-04-21T02:32:55.898+0000] {subprocess.py:93} INFO - Error: Invalid value for '--profiles-dir': Path '/home/***/.dbt' does not exist.
[2025-04-21T02:32:56.005+0000] {subprocess.py:97} INFO - Command exited with return code 2
[2025-04-21T02:32:56.012+0000] {taskinstance.py:3310} ERROR - Task failed with exception
Traceback (most recent call last):
  File "/home/airflow/.local/lib/python3.10/site-packages/airflow/models/taskinstance.py", line 767, in _execute_task
    result = _execute_callable(context=context, **execute_callable_kwargs)
  File "/home/airflow/.local/lib/python3.10/site-packages/airflow/models/taskinstance.py", line 733, in _execute_callable
    return ExecutionCallableRunner(
  File "/home/airflow/.local/lib/python3.10/site-packages/airflow/utils/operator_helpers.py", line 252, in run
    return self.func(*args, **kwargs)
  File "/home/airflow/.local/lib/python3.10/site-packages/airflow/models/baseoperator.py", line 406, in wrapper
    return func(self, *args, **kwargs)
  File "/home/airflow/.local/lib/python3.10/site-packages/airflow/operators/bash.py", line 249, in execute
    raise AirflowException(
airflow.exceptions.AirflowException: Bash command failed. The command returned a non-zero exit code 2.
[2025-04-21T02:32:56.014+0000] {taskinstance.py:1225} INFO - Marking task as FAILED. dag_id=dbt_run_dag, task_id=run_dbt_models, run_id=scheduled__2025-04-20T00:00:00+00:00, execution_date=20250420T000000, start_date=20250421T023254, end_date=20250421T023256
[2025-04-21T02:32:56.020+0000] {taskinstance.py:340} INFO - ::group::Post task execution logs
[2025-04-21T02:32:56.021+0000] {standard_task_runner.py:124} ERROR - Failed to execute job 5 for task run_dbt_models (Bash command failed. The command returned a non-zero exit code 2.; 457)
Traceback (most recent call last):
  File "/home/airflow/.local/lib/python3.10/site-packages/airflow/task/task_runner/standard_task_runner.py", line 117, in _start_by_fork
    ret = args.func(args, dag=self.dag)
  File "/home/airflow/.local/lib/python3.10/site-packages/airflow/cli/cli_config.py", line 49, in command
    return func(*args, **kwargs)
  File "/home/airflow/.local/lib/python3.10/site-packages/airflow/utils/cli.py", line 115, in wrapper
    return f(*args, **kwargs)
  File "/home/airflow/.local/lib/python3.10/site-packages/airflow/cli/commands/task_command.py", line 483, in task_run
    task_return_code = _run_task_by_selected_method(args, _dag, ti)
  File "/home/airflow/.local/lib/python3.10/site-packages/airflow/cli/commands/task_command.py", line 256, in _run_task_by_selected_method
    return _run_raw_task(args, ti)
  File "/home/airflow/.local/lib/python3.10/site-packages/airflow/cli/commands/task_command.py", line 341, in _run_raw_task
    return ti._run_raw_task(
  File "/home/airflow/.local/lib/python3.10/site-packages/airflow/utils/session.py", line 97, in wrapper
    return func(*args, session=session, **kwargs)
  File "/home/airflow/.local/lib/python3.10/site-packages/airflow/models/taskinstance.py", line 3004, in _run_raw_task
    return _run_raw_task(
  File "/home/airflow/.local/lib/python3.10/site-packages/airflow/models/taskinstance.py", line 273, in _run_raw_task
    TaskInstance._execute_task_with_callbacks(
  File "/home/airflow/.local/lib/python3.10/site-packages/airflow/models/taskinstance.py", line 3158, in _execute_task_with_callbacks
    result = self._execute_task(context, task_orig)
  File "/home/airflow/.local/lib/python3.10/site-packages/airflow/models/taskinstance.py", line 3182, in _execute_task
    return _execute_task(self, context, task_orig)
  File "/home/airflow/.local/lib/python3.10/site-packages/airflow/models/taskinstance.py", line 767, in _execute_task
    result = _execute_callable(context=context, **execute_callable_kwargs)
  File "/home/airflow/.local/lib/python3.10/site-packages/airflow/models/taskinstance.py", line 733, in _execute_callable
    return ExecutionCallableRunner(
  File "/home/airflow/.local/lib/python3.10/site-packages/airflow/utils/operator_helpers.py", line 252, in run
    return self.func(*args, **kwargs)
  File "/home/airflow/.local/lib/python3.10/site-packages/airflow/models/baseoperator.py", line 406, in wrapper
    return func(self, *args, **kwargs)
  File "/home/airflow/.local/lib/python3.10/site-packages/airflow/operators/bash.py", line 249, in execute
    raise AirflowException(
airflow.exceptions.AirflowException: Bash command failed. The command returned a non-zero exit code 2.
[2025-04-21T02:32:56.053+0000] {local_task_job_runner.py:266} INFO - Task exited with return code 1
[2025-04-21T02:32:56.064+0000] {taskinstance.py:3900} INFO - 0 downstream tasks scheduled from follow-on schedule check
[2025-04-21T02:32:56.064+0000] {local_task_job_runner.py:245} INFO - ::endgroup::
