[2025-04-19T01:54:45.223+0000] {local_task_job_runner.py:123} INFO - ::group::Pre task execution logs
[2025-04-19T01:54:45.228+0000] {taskinstance.py:2612} INFO - Dependencies all met for dep_context=non-requeueable deps ti=<TaskInstance: spotify_etl_dag.load_spotify_csv_to_snowflake manual__2025-04-19T01:47:16.251538+00:00 [queued]>
[2025-04-19T01:54:45.231+0000] {taskinstance.py:2612} INFO - Dependencies all met for dep_context=requeueable deps ti=<TaskInstance: spotify_etl_dag.load_spotify_csv_to_snowflake manual__2025-04-19T01:47:16.251538+00:00 [queued]>
[2025-04-19T01:54:45.231+0000] {taskinstance.py:2865} INFO - Starting attempt 3 of 3
[2025-04-19T01:54:45.235+0000] {taskinstance.py:2888} INFO - Executing <Task(PythonOperator): load_spotify_csv_to_snowflake> on 2025-04-19 01:47:16.251538+00:00
[2025-04-19T01:54:45.240+0000] {standard_task_runner.py:104} INFO - Running: ['***', 'tasks', 'run', 'spotify_etl_dag', 'load_spotify_csv_to_snowflake', 'manual__2025-04-19T01:47:16.251538+00:00', '--job-id', '9', '--raw', '--subdir', 'DAGS_FOLDER/spotify_etl_dag.py', '--cfg-path', '/tmp/tmpbwikr7q7']
[2025-04-19T01:54:45.241+0000] {standard_task_runner.py:105} INFO - Job 9: Subtask load_spotify_csv_to_snowflake
[2025-04-19T01:54:45.241+0000] {logging_mixin.py:190} WARNING - /home/***/.local/lib/python3.12/site-packages/***/task/task_runner/standard_task_runner.py:70 DeprecationWarning: This process (pid=882) is multi-threaded, use of fork() may lead to deadlocks in the child.
[2025-04-19T01:54:45.242+0000] {standard_task_runner.py:72} INFO - Started process 885 to run task
[2025-04-19T01:54:45.259+0000] {task_command.py:467} INFO - Running <TaskInstance: spotify_etl_dag.load_spotify_csv_to_snowflake manual__2025-04-19T01:47:16.251538+00:00 [running]> on host 333cd928e04a
[2025-04-19T01:54:45.283+0000] {taskinstance.py:3131} INFO - Exporting env vars: AIRFLOW_CTX_DAG_OWNER='***' AIRFLOW_CTX_DAG_ID='spotify_etl_dag' AIRFLOW_CTX_TASK_ID='load_spotify_csv_to_snowflake' AIRFLOW_CTX_EXECUTION_DATE='2025-04-19T01:47:16.251538+00:00' AIRFLOW_CTX_TRY_NUMBER='3' AIRFLOW_CTX_DAG_RUN_ID='manual__2025-04-19T01:47:16.251538+00:00'
[2025-04-19T01:54:45.283+0000] {taskinstance.py:731} INFO - ::endgroup::
[2025-04-19T01:54:45.309+0000] {base.py:84} INFO - Retrieving connection 'snowflake_conn'
[2025-04-19T01:54:45.309+0000] {connection.py:413} INFO - Snowflake Connector for Python Version: 3.12.1, Python Version: 3.12.5, Platform: Linux-6.10.14-linuxkit-aarch64-with-glibc2.36
[2025-04-19T01:54:45.310+0000] {connection.py:1196} INFO - Connecting to GLOBAL Snowflake domain
[2025-04-19T01:54:45.310+0000] {connection.py:1277} INFO - This connection is in OCSP Fail Open Mode. TLS Certificates would be checked for validity and revocation status. Any other Certificate Revocation related exceptions or OCSP Responder failures would be disregarded in favor of connectivity.
[2025-04-19T01:55:42.951+0000] {taskinstance.py:3310} ERROR - Task failed with exception
Traceback (most recent call last):
  File "/home/airflow/.local/lib/python3.12/site-packages/airflow/models/taskinstance.py", line 767, in _execute_task
    result = _execute_callable(context=context, **execute_callable_kwargs)
             ^^^^^^^^^^^^^^^^^^^^^^^^^^^^^^^^^^^^^^^^^^^^^^^^^^^^^^^^^^^^^
  File "/home/airflow/.local/lib/python3.12/site-packages/airflow/models/taskinstance.py", line 733, in _execute_callable
    return ExecutionCallableRunner(
           ^^^^^^^^^^^^^^^^^^^^^^^^
  File "/home/airflow/.local/lib/python3.12/site-packages/airflow/utils/operator_helpers.py", line 252, in run
    return self.func(*args, **kwargs)
           ^^^^^^^^^^^^^^^^^^^^^^^^^^
  File "/home/airflow/.local/lib/python3.12/site-packages/airflow/models/baseoperator.py", line 406, in wrapper
    return func(self, *args, **kwargs)
           ^^^^^^^^^^^^^^^^^^^^^^^^^^^
  File "/home/airflow/.local/lib/python3.12/site-packages/airflow/operators/python.py", line 238, in execute
    return_value = self.execute_callable()
                   ^^^^^^^^^^^^^^^^^^^^^^^
  File "/home/airflow/.local/lib/python3.12/site-packages/airflow/operators/python.py", line 256, in execute_callable
    return runner.run(*self.op_args, **self.op_kwargs)
           ^^^^^^^^^^^^^^^^^^^^^^^^^^^^^^^^^^^^^^^^^^^
  File "/home/airflow/.local/lib/python3.12/site-packages/airflow/utils/operator_helpers.py", line 252, in run
    return self.func(*args, **kwargs)
           ^^^^^^^^^^^^^^^^^^^^^^^^^^
  File "/opt/airflow/dags/load_spotify_to_snowflake.py", line 29, in load_csv_to_snowflake
    cursor.execute("""
  File "/home/airflow/.local/lib/python3.12/site-packages/snowflake/connector/cursor.py", line 1087, in execute
    Error.errorhandler_wrapper(self.connection, self, error_class, errvalue)
  File "/home/airflow/.local/lib/python3.12/site-packages/snowflake/connector/errors.py", line 284, in errorhandler_wrapper
    handed_over = Error.hand_to_other_handler(
                  ^^^^^^^^^^^^^^^^^^^^^^^^^^^^
  File "/home/airflow/.local/lib/python3.12/site-packages/snowflake/connector/errors.py", line 339, in hand_to_other_handler
    cursor.errorhandler(connection, cursor, error_class, error_value)
  File "/home/airflow/.local/lib/python3.12/site-packages/snowflake/connector/errors.py", line 215, in default_errorhandler
    raise error_class(
snowflake.connector.errors.ProgrammingError: 000904 (42000): 01bbc893-0305-0010-0004-59ff0022c486: SQL compilation error: error line 5 at position 95
invalid identifier 'NAN'
[2025-04-19T01:55:42.977+0000] {taskinstance.py:1225} INFO - Marking task as FAILED. dag_id=spotify_etl_dag, task_id=load_spotify_csv_to_snowflake, run_id=manual__2025-04-19T01:47:16.251538+00:00, execution_date=20250419T014716, start_date=20250419T015445, end_date=20250419T015542
[2025-04-19T01:55:42.987+0000] {taskinstance.py:340} INFO - ::group::Post task execution logs
[2025-04-19T01:55:42.988+0000] {standard_task_runner.py:124} ERROR - Failed to execute job 9 for task load_spotify_csv_to_snowflake (000904 (42000): 01bbc893-0305-0010-0004-59ff0022c486: SQL compilation error: error line 5 at position 95
invalid identifier 'NAN'; 885)
Traceback (most recent call last):
  File "/home/airflow/.local/lib/python3.12/site-packages/airflow/task/task_runner/standard_task_runner.py", line 117, in _start_by_fork
    ret = args.func(args, dag=self.dag)
          ^^^^^^^^^^^^^^^^^^^^^^^^^^^^^
  File "/home/airflow/.local/lib/python3.12/site-packages/airflow/cli/cli_config.py", line 49, in command
    return func(*args, **kwargs)
           ^^^^^^^^^^^^^^^^^^^^^
  File "/home/airflow/.local/lib/python3.12/site-packages/airflow/utils/cli.py", line 115, in wrapper
    return f(*args, **kwargs)
           ^^^^^^^^^^^^^^^^^^
  File "/home/airflow/.local/lib/python3.12/site-packages/airflow/cli/commands/task_command.py", line 483, in task_run
    task_return_code = _run_task_by_selected_method(args, _dag, ti)
                       ^^^^^^^^^^^^^^^^^^^^^^^^^^^^^^^^^^^^^^^^^^^^
  File "/home/airflow/.local/lib/python3.12/site-packages/airflow/cli/commands/task_command.py", line 256, in _run_task_by_selected_method
    return _run_raw_task(args, ti)
           ^^^^^^^^^^^^^^^^^^^^^^^
  File "/home/airflow/.local/lib/python3.12/site-packages/airflow/cli/commands/task_command.py", line 341, in _run_raw_task
    return ti._run_raw_task(
           ^^^^^^^^^^^^^^^^^
  File "/home/airflow/.local/lib/python3.12/site-packages/airflow/utils/session.py", line 97, in wrapper
    return func(*args, session=session, **kwargs)
           ^^^^^^^^^^^^^^^^^^^^^^^^^^^^^^^^^^^^^^
  File "/home/airflow/.local/lib/python3.12/site-packages/airflow/models/taskinstance.py", line 3004, in _run_raw_task
    return _run_raw_task(
           ^^^^^^^^^^^^^^
  File "/home/airflow/.local/lib/python3.12/site-packages/airflow/models/taskinstance.py", line 273, in _run_raw_task
    TaskInstance._execute_task_with_callbacks(
  File "/home/airflow/.local/lib/python3.12/site-packages/airflow/models/taskinstance.py", line 3158, in _execute_task_with_callbacks
    result = self._execute_task(context, task_orig)
             ^^^^^^^^^^^^^^^^^^^^^^^^^^^^^^^^^^^^^^
  File "/home/airflow/.local/lib/python3.12/site-packages/airflow/models/taskinstance.py", line 3182, in _execute_task
    return _execute_task(self, context, task_orig)
           ^^^^^^^^^^^^^^^^^^^^^^^^^^^^^^^^^^^^^^^
  File "/home/airflow/.local/lib/python3.12/site-packages/airflow/models/taskinstance.py", line 767, in _execute_task
    result = _execute_callable(context=context, **execute_callable_kwargs)
             ^^^^^^^^^^^^^^^^^^^^^^^^^^^^^^^^^^^^^^^^^^^^^^^^^^^^^^^^^^^^^
  File "/home/airflow/.local/lib/python3.12/site-packages/airflow/models/taskinstance.py", line 733, in _execute_callable
    return ExecutionCallableRunner(
           ^^^^^^^^^^^^^^^^^^^^^^^^
  File "/home/airflow/.local/lib/python3.12/site-packages/airflow/utils/operator_helpers.py", line 252, in run
    return self.func(*args, **kwargs)
           ^^^^^^^^^^^^^^^^^^^^^^^^^^
  File "/home/airflow/.local/lib/python3.12/site-packages/airflow/models/baseoperator.py", line 406, in wrapper
    return func(self, *args, **kwargs)
           ^^^^^^^^^^^^^^^^^^^^^^^^^^^
  File "/home/airflow/.local/lib/python3.12/site-packages/airflow/operators/python.py", line 238, in execute
    return_value = self.execute_callable()
                   ^^^^^^^^^^^^^^^^^^^^^^^
  File "/home/airflow/.local/lib/python3.12/site-packages/airflow/operators/python.py", line 256, in execute_callable
    return runner.run(*self.op_args, **self.op_kwargs)
           ^^^^^^^^^^^^^^^^^^^^^^^^^^^^^^^^^^^^^^^^^^^
  File "/home/airflow/.local/lib/python3.12/site-packages/airflow/utils/operator_helpers.py", line 252, in run
    return self.func(*args, **kwargs)
           ^^^^^^^^^^^^^^^^^^^^^^^^^^
  File "/opt/airflow/dags/load_spotify_to_snowflake.py", line 29, in load_csv_to_snowflake
    cursor.execute("""
  File "/home/airflow/.local/lib/python3.12/site-packages/snowflake/connector/cursor.py", line 1087, in execute
    Error.errorhandler_wrapper(self.connection, self, error_class, errvalue)
  File "/home/airflow/.local/lib/python3.12/site-packages/snowflake/connector/errors.py", line 284, in errorhandler_wrapper
    handed_over = Error.hand_to_other_handler(
                  ^^^^^^^^^^^^^^^^^^^^^^^^^^^^
  File "/home/airflow/.local/lib/python3.12/site-packages/snowflake/connector/errors.py", line 339, in hand_to_other_handler
    cursor.errorhandler(connection, cursor, error_class, error_value)
  File "/home/airflow/.local/lib/python3.12/site-packages/snowflake/connector/errors.py", line 215, in default_errorhandler
    raise error_class(
snowflake.connector.errors.ProgrammingError: 000904 (42000): 01bbc893-0305-0010-0004-59ff0022c486: SQL compilation error: error line 5 at position 95
invalid identifier 'NAN'
[2025-04-19T01:55:43.003+0000] {local_task_job_runner.py:266} INFO - Task exited with return code 1
[2025-04-19T01:55:43.021+0000] {taskinstance.py:3900} INFO - 0 downstream tasks scheduled from follow-on schedule check
[2025-04-19T01:55:43.021+0000] {local_task_job_runner.py:245} INFO - ::endgroup::
